[
    {
        "type": "message",
        "user": "U1AU8DRQR",
        "text": "<@U1HFNJB50> same for me",
        "ts": "1480338741.003252"
    },
    {
        "type": "message",
        "user": "U0KPFAZNF",
        "text": "<@U1HFNJB50> the cobertura report failure is a red herring",
        "ts": "1480339555.003253"
    },
    {
        "type": "message",
        "user": "U0KPFAZNF",
        "text": "the actual failure was just above that, in the gossip UT",
        "ts": "1480339566.003254"
    },
    {
        "type": "message",
        "user": "U0KPFAZNF",
        "text": "In this case, the offending test was: FAIL\t<http:\/\/github.com\/hyperledger\/fabric\/gossip\/state|github.com\/hyperledger\/fabric\/gossip\/state>\t15.341s",
        "ts": "1480339611.003255"
    },
    {
        "type": "message",
        "user": "U0KPFAZNF",
        "text": "that said, it seems like the error did not propagate properly such that the cobertura portion was still trying to locate the report",
        "ts": "1480339671.003256"
    },
    {
        "type": "message",
        "user": "U0KPFAZNF",
        "text": "<@U0YK3KKCY> There seems to be something wrong with the s390x CI engine",
        "ts": "1480339799.003257"
    },
    {
        "type": "message",
        "user": "U0KPFAZNF",
        "text": "<https:\/\/jenkins.hyperledger.org\/job\/fabric-baseimage-verify-docker-s390x\/7\/console>",
        "ts": "1480339803.003258"
    },
    {
        "type": "message",
        "user": "U1HFNJB50",
        "text": "So cobertura tries to build up the report, while there is a test failure hence no report generated, as a consequence IOException\u2026 am I getting it right?",
        "ts": "1480339817.003259"
    },
    {
        "type": "message",
        "user": "U0KPFAZNF",
        "text": "<@U0YK3KKCY>: reference <https:\/\/gerrit.hyperledger.org\/r\/#\/c\/2795\/1>",
        "ts": "1480339836.003260"
    },
    {
        "type": "message",
        "user": "U0KPFAZNF",
        "text": "<@U1HFNJB50> yes, that seems to be the case...whats supposed to happen is the UTs run, piping their output into gocov-xml which generates report.xml",
        "ts": "1480339878.003261"
    },
    {
        "type": "message",
        "user": "U0KPFAZNF",
        "text": "a UT then fails, which should stop the whole pipeline",
        "ts": "1480339886.003262"
    },
    {
        "type": "message",
        "user": "U0KPFAZNF",
        "text": "but instead, the next phase which tries to process the report.xml still runs",
        "ts": "1480339897.003263"
    },
    {
        "type": "message",
        "user": "U0KPFAZNF",
        "text": "so, the real problem is that a UT failed",
        "ts": "1480339905.003264"
    },
    {
        "type": "message",
        "user": "U1HFNJB50",
        "text": "Oh, I see thanks",
        "ts": "1480339913.003265"
    },
    {
        "type": "message",
        "user": "U0KPFAZNF",
        "text": "but a secondary problem is that the UT failure was not detected",
        "ts": "1480339915.003266"
    },
    {
        "type": "message",
        "user": "U1HFNJB50",
        "text": "will take a look into UT",
        "ts": "1480339927.003267"
    },
    {
        "type": "message",
        "user": "U0KPFAZNF",
        "text": "<@U11HH3P7Y> can you investigate the secondary problem mentioned above?",
        "ts": "1480340087.003268"
    },
    {
        "type": "message",
        "user": "U0KPFAZNF",
        "text": "Not sure where the disconnect is occuring, but the UT fail should have propagated in a way that you don't try to process the report",
        "ts": "1480340122.003269"
    },
    {
        "type": "message",
        "user": "U0KPFAZNF",
        "text": "(it could be my fault\/problem, to be clear)",
        "ts": "1480340136.003270"
    },
    {
        "type": "message",
        "user": "U0KPFAZNF",
        "text": "but if you can investigate it, that would be helpful",
        "ts": "1480340153.003271"
    },
    {
        "type": "message",
        "user": "U11HH3P7Y",
        "text": "<@U0KPFAZNF> looking into the coverage report issue.",
        "ts": "1480342510.003272"
    },
    {
        "type": "message",
        "user": "U0YK3KKCY",
        "text": "<@U0KPFAZNF> i'll take a look.  re: s390 ci for base image",
        "ts": "1480343059.003273"
    },
    {
        "type": "message",
        "user": "U0YK3KKCY",
        "text": "<@U0KPFAZNF> <@U11HH3P7Y>, please resubmit verify job for the baseimage patch",
        "ts": "1480343207.003274"
    },
    {
        "type": "message",
        "user": "U0YK3KKCY",
        "text": "the issue has been resolved.",
        "ts": "1480343331.003275",
        "reactions": [
            {
                "name": "+1",
                "users": [
                    "U10Q62R8X",
                    "U11NUTP4L"
                ],
                "count": 2
            }
        ]
    },
    {
        "type": "message",
        "user": "U11HH3P7Y",
        "text": "ok",
        "ts": "1480343823.003276"
    },
    {
        "type": "message",
        "user": "U11HH3P7Y",
        "text": "<@U0YK3KKCY>: getting same error ``` Cannot connect to the Docker daemon. Is the docker daemon running on this host?\n00:00:05.568 Build step 'Execute shell' marked build as failure\n00:00:05.730 Finished: FAILURE```",
        "ts": "1480344065.003277"
    },
    {
        "type": "message",
        "user": "U0YK3KKCY",
        "text": "ok are you using hyp-z-linuxone-3 ?",
        "ts": "1480344106.003278"
    },
    {
        "type": "message",
        "user": "U0YK3KKCY",
        "text": "ah i think i see the issue ( #2)... let me fix this",
        "ts": "1480344196.003279"
    },
    {
        "type": "message",
        "user": "U0YK3KKCY",
        "text": "ok, please try again <@U11HH3P7Y>",
        "ts": "1480344258.003280"
    },
    {
        "type": "message",
        "user": "U11HH3P7Y",
        "text": "yes last one was on #2..",
        "ts": "1480344282.003281"
    },
    {
        "type": "message",
        "user": "U11HH3P7Y",
        "text": "will try",
        "ts": "1480344286.003282"
    },
    {
        "type": "message",
        "user": "U0YK3KKCY",
        "text": "ah, k. i put the fix on #3...",
        "ts": "1480344358.003283"
    },
    {
        "type": "message",
        "user": "U0YK3KKCY",
        "text": "let me check #2",
        "ts": "1480344362.003284"
    },
    {
        "type": "message",
        "user": "U11HH3P7Y",
        "text": "it's working now..",
        "ts": "1480344385.003285"
    },
    {
        "type": "message",
        "user": "U11HH3P7Y",
        "text": "thanks",
        "ts": "1480344392.003286"
    },
    {
        "type": "message",
        "user": "U0YK3KKCY",
        "text": "great!",
        "ts": "1480344425.003287"
    },
    {
        "type": "message",
        "user": "U0KPFAZNF",
        "text": "ty <@U0YK3KKCY>",
        "ts": "1480345395.003288"
    },
    {
        "type": "message",
        "user": "U0YK3KKCY",
        "text": "yqw",
        "ts": "1480345883.003289"
    },
    {
        "type": "message",
        "user": "U0YK3KKCY",
        "text": "<@U11HH3P7Y> let me resolve the out of space issue that i see for those verify jobs.",
        "ts": "1480352845.003290"
    },
    {
        "type": "message",
        "user": "U0YK3KKCY",
        "text": "<@U11HH3P7Y> hyp2 has been fixed. now working on hyp3",
        "ts": "1480353223.003291"
    },
    {
        "type": "message",
        "user": "U11HH3P7Y",
        "text": "ok.. once done will re-trigger this job again",
        "ts": "1480353243.003292"
    },
    {
        "type": "message",
        "user": "U0YK3KKCY",
        "text": "ok... space issues have been resolved. please try again.",
        "ts": "1480353379.003293"
    },
    {
        "type": "message",
        "user": "U0YK3KKCY",
        "text": "<@U11HH3P7Y> good to see the verify job finally completed without error.",
        "ts": "1480355529.003294"
    },
    {
        "type": "message",
        "user": "U11HH3P7Y",
        "text": "yes..",
        "ts": "1480355936.003295"
    },
    {
        "type": "message",
        "user": "U11HH3P7Y",
        "text": "<@U0UHG4VP1>: seems builds are stuck in queue <https:\/\/jenkins.hyperledger.org\/view\/fabric\/>",
        "ts": "1480362315.003296"
    },
    {
        "type": "message",
        "user": "U11HH3P7Y",
        "text": "all queued builds are waiting for hyp-x86_64-3235 executor",
        "ts": "1480362429.003297"
    },
    {
        "type": "message",
        "user": "U0UHG4VP1",
        "text": "<@U11HH3P7Y>: I'll be back from lunch in 20",
        "ts": "1480364479.003298"
    },
    {
        "type": "message",
        "user": "U11HH3P7Y",
        "text": "ok",
        "ts": "1480364595.003299"
    },
    {
        "type": "message",
        "user": "U0UHG4VP1",
        "text": "<@U11HH3P7Y> looks like it cleared up on its own",
        "ts": "1480366619.003300"
    },
    {
        "type": "message",
        "user": "U11HH3P7Y",
        "text": "yes",
        "ts": "1480366668.003301"
    }
]