[
    {
        "type": "message",
        "user": "U0KPFAZNF",
        "text": "<@U0UHG4VP1>: these failures seem to be fairly common now: <https:\/\/jenkins.hyperledger.org\/job\/fabric-verify-x86_64\/2547\/console>",
        "ts": "1478633666.002684"
    },
    {
        "type": "message",
        "user": "U0KPFAZNF",
        "text": "any idea on whats up?",
        "ts": "1478633670.002685"
    },
    {
        "type": "message",
        "user": "U0YK3KKCY",
        "text": "<@U0KPFAZNF>... not sure if you've seen this <https:\/\/issues.jenkins-ci.org\/browse\/JENKINS-28279>",
        "ts": "1478640347.002686"
    },
    {
        "type": "message",
        "user": "U0KPFAZNF",
        "text": "thanks <@U0YK3KKCY>, I had not (but I hadnt looked)",
        "ts": "1478641510.002687"
    },
    {
        "type": "message",
        "user": "U0YK3KKCY",
        "text": "k",
        "ts": "1478641523.002688"
    },
    {
        "type": "message",
        "user": "U0UHG4VP1",
        "text": "since none of our minions are Windows, and they should have SSH baked in, I don't think that's directly the issue. I don't want to dismiss it, though.",
        "ts": "1478642215.002689"
    },
    {
        "type": "message",
        "user": "U0UHG4VP1",
        "text": "ghaskins I did ask our release engineer group about this, and the position seems to be it's network instability. no other project at our provider seems to hit this as often as we do, though",
        "ts": "1478642265.002690"
    },
    {
        "type": "message",
        "user": "U0KPFAZNF",
        "text": "def weird",
        "ts": "1478642303.002691"
    },
    {
        "type": "message",
        "user": "U0UHG4VP1",
        "text": "agreed",
        "ts": "1478643293.002692"
    }
]