[
    {
        "type": "message",
        "user": "U1F1CU61Y",
        "text": "<@U2LHDBZM0>  what do you mean by that ? Can you please explain the same ?",
        "ts": "1480666593.000265"
    },
    {
        "type": "message",
        "user": "U0YNFB22X",
        "text": "<@U2LHDBZM0> raise a runtime exception in your chaincode invoke",
        "ts": "1480666701.000266"
    },
    {
        "type": "message",
        "user": "U2LHDBZM0",
        "text": "Actually, I am running two chaincode and I want to throw runtime exception from one chaincode and want to catch in another chaincode.",
        "ts": "1480666933.000267"
    },
    {
        "type": "message",
        "user": "U2LHDBZM0",
        "text": "<@U0YNFB22X> <@U1F1CU61Y>",
        "ts": "1480666956.000268"
    },
    {
        "type": "message",
        "user": "U2LHDBZM0",
        "text": "But nothing is happening in another chaincode which is catching an exception.",
        "ts": "1480667013.000269"
    },
    {
        "type": "message",
        "user": "U0YNFB22X",
        "text": "Submitting the transaction is asyn. ",
        "ts": "1480667109.000270"
    },
    {
        "type": "message",
        "user": "U0YNFB22X",
        "text": "So you will have to look into block events or something to accomplish this I believe",
        "ts": "1480667165.000271"
    },
    {
        "type": "message",
        "user": "U2LHDBZM0",
        "text": "Suppose, I have two chaincode CC1 and CC2, and I am invoking CC1 and internally CC1 is invoking CC2. And I am checking some variable X in CC2 i.e if it is equal to 10 then go further otherwise throw some exception or Error. Then later I want CC1 to fail the transaction if this happens.",
        "ts": "1480667464.000272"
    },
    {
        "type": "message",
        "user": "U2LHDBZM0",
        "text": "I tested with RuntimeException in CC2 and try to catch the exception in CC1 but CC1 is not going into catch block while CC1 is throwing an exception and displaying it on the terminal.",
        "ts": "1480667607.000273"
    },
    {
        "type": "message",
        "user": "U2LHDBZM0",
        "text": "This is the whole scenario.",
        "ts": "1480667617.000274"
    },
    {
        "type": "message",
        "user": "U0YNFB22X",
        "text": "When cc1 submits the transaction to cc2 all it gets is a transaction id, and gets the control back. So you won't be able to catch the exception in cc1.",
        "ts": "1480667718.000275"
    },
    {
        "type": "message",
        "user": "U0YNFB22X",
        "text": "The transaction execution in cc2 happens async after it's submitted",
        "ts": "1480667748.000276"
    },
    {
        "type": "message",
        "user": "U2LHDBZM0",
        "text": "Ok",
        "ts": "1480667982.000277"
    }
]